<robot name = "robot">
    <link name="0">
        <inertial>
            <origin xyz="0 0 0.42211178048401005" rpy="0 0 0"/>
            <mass value="1" />
            <inertia ixx="100" ixy="0" ixz="0" iyy="100" iyz="0" izz="100" />
        </inertial>
        <visual>
            <origin xyz="0 0 0.42211178048401005" rpy="0 0 0"/>
            <geometry>
                <box size="0.5060868132530039 0.42281782326665684 0.8442235609680201" />
            </geometry>
            <material name="Green">
                <color rgba="0 1 0 1.0"/>
            </material>
        </visual>
        <collision>
            <origin xyz="0 0 0.42211178048401005" rpy="0 0 0"/>
            <geometry>
                <box size="0.5060868132530039 0.42281782326665684 0.8442235609680201" />
            </geometry>
        </collision>
    </link>
    <joint name="0_1" type="revolute">
       <parent link="0"/>
       <child  link="1"/>
       <origin rpy="0 0 0" xyz="0.25304340662650193 0.0 0.0" />
     <axis xyz="0 1 0"/>
       <limit effort="0.0" lower="-3.14159" upper="3.14159" velocity="0.0"/>
    </joint>
    <link name="1">
        <inertial>
            <origin xyz="0.023523303041866114 0.0 0.0" rpy="0 0 0"/>
            <mass value="1" />
            <inertia ixx="100" ixy="0" ixz="0" iyy="100" iyz="0" izz="100" />
        </inertial>
        <visual>
            <origin xyz="0.023523303041866114 0.0 0.0" rpy="0 0 0"/>
            <geometry>
                <box size="0.04704660608373223 0.5424710356899762 0.934802636479536" />
            </geometry>
            <material name="Blue">
                <color rgba="0 0 1 1.0"/>
            </material>
        </visual>
        <collision>
            <origin xyz="0.023523303041866114 0.0 0.0" rpy="0 0 0"/>
            <geometry>
                <box size="0.04704660608373223 0.5424710356899762 0.934802636479536" />
            </geometry>
        </collision>
    </link>
    <joint name="1_2" type="revolute">
       <parent link="1"/>
       <child  link="2"/>
       <origin rpy="0 0 0" xyz="0.467401318239768 0.0 0.467401318239768" />
     <axis xyz="1 0 0"/>
       <limit effort="0.0" lower="-3.14159" upper="3.14159" velocity="0.0"/>
    </joint>
    <link name="2">
        <inertial>
            <origin xyz="0.0 0.0 0.4971643239612152" rpy="0 0 0"/>
            <mass value="1" />
            <inertia ixx="100" ixy="0" ixz="0" iyy="100" iyz="0" izz="100" />
        </inertial>
        <visual>
            <origin xyz="0.0 0.0 0.4971643239612152" rpy="0 0 0"/>
            <geometry>
                <box size="0.7014064301288392 0.751450437347119 0.9943286479224304" />
            </geometry>
            <material name="Green">
                <color rgba="0 1 0 1.0"/>
            </material>
        </visual>
        <collision>
            <origin xyz="0.0 0.0 0.4971643239612152" rpy="0 0 0"/>
            <geometry>
                <box size="0.7014064301288392 0.751450437347119 0.9943286479224304" />
            </geometry>
        </collision>
    </link>
    <joint name="2_3" type="revolute">
       <parent link="2"/>
       <child  link="3"/>
       <origin rpy="0 0 0" xyz="0.0 0.3757252186735595 0.3757252186735595" />
     <axis xyz="1 0 0"/>
       <limit effort="0.0" lower="-3.14159" upper="3.14159" velocity="0.0"/>
    </joint>
    <link name="3">
        <inertial>
            <origin xyz="0.0 0.17669047230571333 0.0" rpy="0 0 0"/>
            <mass value="1" />
            <inertia ixx="100" ixy="0" ixz="0" iyy="100" iyz="0" izz="100" />
        </inertial>
        <visual>
            <origin xyz="0.0 0.17669047230571333 0.0" rpy="0 0 0"/>
            <geometry>
                <box size="0.6492919287571762 0.35338094461142666 0.4177036520300148" />
            </geometry>
            <material name="Blue">
                <color rgba="0 0 1 1.0"/>
            </material>
        </visual>
        <collision>
            <origin xyz="0.0 0.17669047230571333 0.0" rpy="0 0 0"/>
            <geometry>
                <box size="0.6492919287571762 0.35338094461142666 0.4177036520300148" />
            </geometry>
        </collision>
    </link>
    <joint name="3_4" type="revolute">
       <parent link="3"/>
       <child  link="4"/>
       <origin rpy="0 0 0" xyz="0.3246459643785881 0.3246459643785881 0.0" />
     <axis xyz="0 1 0"/>
       <limit effort="0.0" lower="-3.14159" upper="3.14159" velocity="0.0"/>
    </joint>
    <link name="4">
        <inertial>
            <origin xyz="0.07889314956364202 0.0 0.0" rpy="0 0 0"/>
            <mass value="1" />
            <inertia ixx="100" ixy="0" ixz="0" iyy="100" iyz="0" izz="100" />
        </inertial>
        <visual>
            <origin xyz="0.07889314956364202 0.0 0.0" rpy="0 0 0"/>
            <geometry>
                <box size="0.15778629912728404 0.5183753365567384 0.3405919957621396" />
            </geometry>
            <material name="Blue">
                <color rgba="0 0 1 1.0"/>
            </material>
        </visual>
        <collision>
            <origin xyz="0.07889314956364202 0.0 0.0" rpy="0 0 0"/>
            <geometry>
                <box size="0.15778629912728404 0.5183753365567384 0.3405919957621396" />
            </geometry>
        </collision>
    </link>
    <joint name="4_5" type="revolute">
       <parent link="4"/>
       <child  link="5"/>
       <origin rpy="0 0 0" xyz="0.2591876682783692 0.2591876682783692 0.0" />
     <axis xyz="1 0 0"/>
       <limit effort="0.0" lower="-3.14159" upper="3.14159" velocity="0.0"/>
    </joint>
    <link name="5">
        <inertial>
            <origin xyz="0.0 0.053431213940120396 0.0" rpy="0 0 0"/>
            <mass value="1" />
            <inertia ixx="100" ixy="0" ixz="0" iyy="100" iyz="0" izz="100" />
        </inertial>
        <visual>
            <origin xyz="0.0 0.053431213940120396 0.0" rpy="0 0 0"/>
            <geometry>
                <box size="0.11135753165312388 0.10686242788024079 0.1697412837080099" />
            </geometry>
            <material name="Blue">
                <color rgba="0 0 1 1.0"/>
            </material>
        </visual>
        <collision>
            <origin xyz="0.0 0.053431213940120396 0.0" rpy="0 0 0"/>
            <geometry>
                <box size="0.11135753165312388 0.10686242788024079 0.1697412837080099" />
            </geometry>
        </collision>
    </link>
    <joint name="5_6" type="revolute">
       <parent link="5"/>
       <child  link="6"/>
       <origin rpy="0 0 0" xyz="0.0 0.10686242788024079 0.0" />
     <axis xyz="1 0 0"/>
       <limit effort="0.0" lower="-3.14159" upper="3.14159" velocity="0.0"/>
    </joint>
    <link name="6">
        <inertial>
            <origin xyz="0.0 0.13477520721525837 0.0" rpy="0 0 0"/>
            <mass value="1" />
            <inertia ixx="100" ixy="0" ixz="0" iyy="100" iyz="0" izz="100" />
        </inertial>
        <visual>
            <origin xyz="0.0 0.13477520721525837 0.0" rpy="0 0 0"/>
            <geometry>
                <box size="0.08773858716176473 0.26955041443051675 0.5380362044694998" />
            </geometry>
            <material name="Green">
                <color rgba="0 1 0 1.0"/>
            </material>
        </visual>
        <collision>
            <origin xyz="0.0 0.13477520721525837 0.0" rpy="0 0 0"/>
            <geometry>
                <box size="0.08773858716176473 0.26955041443051675 0.5380362044694998" />
            </geometry>
        </collision>
    </link>
    <joint name="6_7" type="revolute">
       <parent link="6"/>
       <child  link="7"/>
       <origin rpy="0 0 0" xyz="0.0 0.2690181022347499 0.2690181022347499" />
     <axis xyz="1 0 0"/>
       <limit effort="0.0" lower="-3.14159" upper="3.14159" velocity="0.0"/>
    </joint>
    <link name="7">
        <inertial>
            <origin xyz="0.0 0.0 0.03252685162190538" rpy="0 0 0"/>
            <mass value="1" />
            <inertia ixx="100" ixy="0" ixz="0" iyy="100" iyz="0" izz="100" />
        </inertial>
        <visual>
            <origin xyz="0.0 0.0 0.03252685162190538" rpy="0 0 0"/>
            <geometry>
                <box size="0.523210054589652 0.05390180663409538 0.06505370324381075" />
            </geometry>
            <material name="Blue">
                <color rgba="0 0 1 1.0"/>
            </material>
        </visual>
        <collision>
            <origin xyz="0.0 0.0 0.03252685162190538" rpy="0 0 0"/>
            <geometry>
                <box size="0.523210054589652 0.05390180663409538 0.06505370324381075" />
            </geometry>
        </collision>
    </link>
    <joint name="7_8" type="revolute">
       <parent link="7"/>
       <child  link="8"/>
       <origin rpy="0 0 0" xyz="0.261605027294826 0.0 0.261605027294826" />
     <axis xyz="0 1 0"/>
       <limit effort="0.0" lower="-3.14159" upper="3.14159" velocity="0.0"/>
    </joint>
    <link name="8">
        <inertial>
            <origin xyz="0.481469687443275 0.0 0.0" rpy="0 0 0"/>
            <mass value="1" />
            <inertia ixx="100" ixy="0" ixz="0" iyy="100" iyz="0" izz="100" />
        </inertial>
        <visual>
            <origin xyz="0.481469687443275 0.0 0.0" rpy="0 0 0"/>
            <geometry>
                <box size="0.96293937488655 0.801963275342113 0.0585349403823504" />
            </geometry>
            <material name="Blue">
                <color rgba="0 0 1 1.0"/>
            </material>
        </visual>
        <collision>
            <origin xyz="0.481469687443275 0.0 0.0" rpy="0 0 0"/>
            <geometry>
                <box size="0.96293937488655 0.801963275342113 0.0585349403823504" />
            </geometry>
        </collision>
    </link>
    <joint name="8_9" type="revolute">
       <parent link="8"/>
       <child  link="9"/>
       <origin rpy="0 0 0" xyz="0.0292674701911752 0.0 0.0292674701911752" />
     <axis xyz="1 0 0"/>
       <limit effort="0.0" lower="-3.14159" upper="3.14159" velocity="0.0"/>
    </joint>
    <link name="9">
        <inertial>
            <origin xyz="0.0 0.0 0.35987350726468526" rpy="0 0 0"/>
            <mass value="1" />
            <inertia ixx="100" ixy="0" ixz="0" iyy="100" iyz="0" izz="100" />
        </inertial>
        <visual>
            <origin xyz="0.0 0.0 0.35987350726468526" rpy="0 0 0"/>
            <geometry>
                <box size="0.45953874601103684 0.8879719146668597 0.7197470145293705" />
            </geometry>
            <material name="Blue">
                <color rgba="0 0 1 1.0"/>
            </material>
        </visual>
        <collision>
            <origin xyz="0.0 0.0 0.35987350726468526" rpy="0 0 0"/>
            <geometry>
                <box size="0.45953874601103684 0.8879719146668597 0.7197470145293705" />
            </geometry>
        </collision>
    </link>
    <joint name="9_10" type="revolute">
       <parent link="9"/>
       <child  link="10"/>
       <origin rpy="0 0 0" xyz="0.0 0.0 0.7197470145293705" />
     <axis xyz="1 0 0"/>
       <limit effort="0.0" lower="-3.14159" upper="3.14159" velocity="0.0"/>
    </joint>
    <link name="10">
        <inertial>
            <origin xyz="0.0 0.0 0.36636285612468356" rpy="0 0 0"/>
            <mass value="1" />
            <inertia ixx="100" ixy="0" ixz="0" iyy="100" iyz="0" izz="100" />
        </inertial>
        <visual>
            <origin xyz="0.0 0.0 0.36636285612468356" rpy="0 0 0"/>
            <geometry>
                <box size="0.7122663944550651 0.8767191117323297 0.7327257122493671" />
            </geometry>
            <material name="Blue">
                <color rgba="0 0 1 1.0"/>
            </material>
        </visual>
        <collision>
            <origin xyz="0.0 0.0 0.36636285612468356" rpy="0 0 0"/>
            <geometry>
                <box size="0.7122663944550651 0.8767191117323297 0.7327257122493671" />
            </geometry>
        </collision>
    </link>
</robot>